Workbook

Sheet PADI
A1: LAPORAN PRODUKSI PADI 2025
A2: DINAS PERTANIAN KABUPATEN GARUT
A4: NO | B4: KECAMATAN | C4: Target Produksi Padi Tahun 2025 | D4: HASIL PRODUKSI | P4: TOTAL | Q4: REALISASI
D5: JANUARI | E5: FEBRUARI | F5: MARET | G5: APRIL | H5: MEI | I5: JUNI | J5: JULI | K5: AGUSTUS | L5: SEPTEMBER | M5: OKTOBER | N5: NOVEMBER | O5: DESEMBER
A6: 1 | B6: Cisewu | C6: 30619 | D6: 2475 | E6: 3850 | F6: 4584 | G6: 2930 | H6: 2843 | I6: 5180 | J6: 7119 | K6: 1604 | L6: 3698 | P6: =SUM(D6:O6) -> 34283 | Q6: {=P6/P6C6} -> #NAME?
A7: 2 | B7: Caringin | C7: 35678 | D7: 2967 | E7: 4484 | F7: 2414 | G7: 2189 | H7: 2465 | I7: 3415 | J7: 3732 | K7: 2532 | L7: 2033 | P7: =SUM(D7:O7) -> 26231 | Q7: =P7/C7 -> 0.73521498
A8: 3 | B8: Talegong | C8: 27731 | D8: 3163 | E8: 3795 | F8: 838 | G8: 2190 | H8: 2313 | I8: 2683 | J8: 6486 | K8: 1300 | L8: 3642 | P8: =SUM(D8:O8) -> 26410 | Q8: =P8/C8 -> 0.95236378
A9: 4 | B9: Bungbulang | C9: 51856 | D9: 4070 | E9: 6150 | F9: 5374 | G9: 2358 | H9: 6920 | I9: 5357 | J9: 5209 | K9: 4959 | L9: 1918 | P9: =SUM(D9:O9) -> 42315 | Q9: =P9/C9 -> 0.81600972
A10: 5 | B10: Mekar Mukti | C10: 25612 | D10: 1701 | E10: 3208 | F10: 2244 | G10: 1658 | H10: 1648 | I10: 3346 | J10: 2282 | K10: 1404 | L10: 1111 | P10: =SUM(D10:O10) -> 18602 | Q10: =P10/C10 -> 0.72630017
A11: 6 | B11: Pakenjeng | C11: 37559 | D11: 3477 | E11: 4045 | F11: 4593 | G11: 3006 | H11: 3310 | I11: 4804 | J11: 4332 | K11: 5144 | L11: 3346 | P11: =SUM(D11:O11) -> 36057 | Q11: =P11/C11 -> 0.96000958
A12: 7 | B12: Pamulihan | C12: 6694 | D12: 623 | E12: 525 | F12: 675 | G12: 439 | H12: 486 | I12: 683 | J12: 768 | K12: 699 | L12: 399 | P12: =SUM(D12:O12) -> 5297 | Q12: =P12/C12 -> 0.79130565
A13: 8 | B13: Cikelet | C13: 22707 | D13: 3855 | E13: 2607 | F13: 2019 | G13: 3005 | H13: 2057 | I13: 2855 | J13: 1849 | K13: 1742 | L13: 1697 | P13: =SUM(D13:O13) -> 21686 | Q13: =P13/C13 -> 0.95503589
A14: 9 | B14: Pameungpeuk | C14: 16873 | D14: 1965 | E14: 2310 | F14: 4395 | G14: 988 | H14: 990 | I14: 1742 | J14: 5059 | K14: 234 | L14: 1189 | P14: =SUM(D14:O14) -> 18872 | Q14: =P14/C14 -> 1.1184733
A15: 10 | B15: Cibalong | C15: 21231 | D15: 1221 | E15: 1822 | F15: 1595 | G15: 1333 | H15: 1141 | I15: 1586 | J15: 1031 | K15: 4862 | L15: 1252 | P15: =SUM(D15:O15) -> 15843 | Q15: =P15/C15 -> 0.74622015
A16: 11 | B16: Cisompet | C16: 26222 | D16: 2357 | E16: 3505 | F16: 3112 | G16: 3641 | H16: 2224 | I16: 2667 | J16: 2144 | K16: 2960 | L16: 1774 | P16: =SUM(D16:O16) -> 24384 | Q16: =P16/C16 -> 0.92990619
A17: 12 | B17: Singajaya | C17: 15403 | D17: 1733 | E17: 1696 | F17: 1658 | G17: 1287 | H17: 1416 | I17: 1967 | J17: 2133 | K17: 1960 | L17: 1768 | P17: =SUM(D17:O17) -> 15618 | Q17: =P17/C17 -> 1.0139583
A18: 13 | B18: Cihurip | C18: 9075 | D18: 985 | E18: 1717 | F18: 1246 | G18: 721 | H18: 821 | I18: 1172 | J18: 707 | K18: 740 | L18: 825 | P18: =SUM(D18:O18) -> 8934 | Q18: =P18/C18 -> 0.98446281
... A47: 42 | B47: Selaawi | C47: 12436 | D47: 590 | E47: 3454 | F47: 1212 | G47: 1246 | H47: 1606 | I47: 1149 | J47: 1265 | K47: 1764 | L47: 1071 | P47: =SUM(D47:O47) -> 13357 | Q47: =P47/C47 -> 1.0740592
A48: JUMLAH | C48: =SUM(C6:C47) -> 707237 | D48: =SUM(D6:D47) -> 78308 | E48: =SUM(E6:E47) -> 94086 | F48: =SUM(F6:F47) -> 88530 | G48: =SUM(G6:G47) -> 64348 | H48: =SUM(H6:H47) -> 68002 | I48: =SUM(I6:I47) -> 80875 | J48: =SUM(J6:J47) -> 87519 | ... P48: =SUM(P6:P47) -> 701430 | Q48: =P48/C48 -> 0.99178917

Sheet CABAI
A1: LAPORAN PRODUKSI CABAI 2025
A2: DINAS PERTANIAN KABUPATEN GARUT
A4: NO | B4: KECAMATAN | C4: Target Produksi Cabai Tahun 2025 | D4: HASIL PRODUKSI | P4: TOTAL | Q4: REALISASI
D5: JANUARI | E5: FEBRUARI | F5: MARET | G5: APRIL | H5: MEI | I5: JUNI | J5: JULI | K5: AGUSTUS | L5: SEPTEMBER | M5: OKTOBER | N5: NOVEMBER | O5: DESEMBER
A6: 1 | B6: Cisewu | C6: 4514 | D6: 833 | E6: 2060 | F6: 1013 | G6: 1013 | H6: 1346 | I6: 1306 | J6: 446 | K6: 510 | L6: 207 | P6: =SUM(D6:O6) -> 8734 | Q6: =IFERROR(P6/C6,0) -> 1.9348693
A7: 2 | B7: Caringin | C7: 7452 | D7: 801 | E7: 80 | F7: 0 | G7: 185 | H7: 55 | I7: 17 | J7: 171 | K7: 0 | L7: 284 | P7: =SUM(D7:O7) -> 1593 | Q7: =IFERROR(P7/C7,0) -> 0.21376812
A8: 3 | B8: Talegong | C8: 5669 | D8: 979 | E8: 1964 | F8: 671 | G8: 1179 | H8: 781 | I8: 1057 | J8: 666 | K8: 330 | L8: 318 | P8: =SUM(D8:O8) -> 7945 | Q8: =IFERROR(P8/C8,0) -> 1.4014817
A9: 4 | B9: Bungbulang | C9: 2458 | D9: 350 | E9: 927 | F9: 5639 | G9: 1708 | H9: 1625 | I9: 54 | J9: 1053 | K9: 1631 | L9: 0 | P9: =SUM(D9:O9) -> 12987 | Q9: =IFERROR(P9/C9,0) -> 5.2835639
A10: 5 | B10: Mekar Mukti | C10: 703 | D10: 23 | E10: 27 | F10: 361 | G10: 16 | H10: 128 | I10: 74 | J10: 161 | K10: 93 | L10: 121 | P10: =SUM(D10:O10) -> 1004 | Q10: =IFERROR(P10/C10,0) -> 1.428165
A11: 6 | B11: Pakenjeng | C11: 2845 | D11: 130 | E11: 1038 | F11: 3378 | G11: 236 | H11: 291 | I11: 324 | J11: 220 | K11: 176 | L11: 163 | P11: =SUM(D11:O11) -> 5956 | Q11: =IFERROR(P11/C11,0) -> 2.0934974
A12: 7 | B12: Pamulihan | C12: 3109 | D12: 282 | E12: 192 | F12: 1757 | G12: 450 | H12: 767 | I12: 483 | J12: 149 | K12: 175 | L12: 295 | P12: =SUM(D12:O12) -> 4550 | Q12: =IFERROR(P12/C12,0) -> 1.4634931
A13: 8 | B13: Cikelet | C13: 0 | D13: 6 | E13: 6 | F13: 4 | G13: 102 | H13: 11 | I13: 85 | J13: 52 | K13: 13 | L13: 41 | P13: =SUM(D13:O13) -> 320 | Q13: =IFERROR(P13/C13,0) -> 0
A14: 9 | B14: Pameungpeuk | C14: 15 | D14: 27 | E14: 0 | F14: 0 | G14: 0 | H14: 165 | I14: 0 | J14: 0 | K14: 123 | L14: 32 | P14: =SUM(D14:O14) -> 347 | Q14: =IFERROR(P14/C14,0) -> 23.133333
A15: 10 | B15: Cibalong | C15: 101 | D15: 0 | E15: 0 | F15: 0 | G15: 0 | H15: 0 | I15: 1 | J15: 14 | K15: 0 | L15: 0 | P15: =SUM(D15:O15) -> 15 | Q15: =IFERROR(P15/C15,0) -> 0.14851485
A16: 11 | B16: Cisompet | C16: 72 | D16: 18 | E16: 77 | F16: 8 | G16: 5 | H16: 144 | I16: 112 | J16: 7 | K16: 117 | L16: 0 | P16: =SUM(D16:O16) -> 488 | Q16: =IFERROR(P16/C16,0) -> 6.7777778
A17: 12 | B17: Singajaya | C17: 628 | D17: 15 | E17: 60 | F17: 108 | G17: 77 | H17: 60 | I17: 45 | J17: 46 | K17: 45 | L17: 32 | P17: =SUM(D17:O17) -> 488 | Q17: =IFERROR(P17/C17,0) -> 0.77707006
... A47: 42 | B47: Selaawi | C47: 0 | D47: 0 | E47: 20 | F47: 20 | G47: 0 | H47: 0 | I47: 7 | J47: 14 | K47: 7 | L47: 0 | P47: =SUM(D47:O47) -> 68 | Q47: =IFERROR(P47/C47,0) -> 0
A48: JUMLAH | C48: =SUM(C6:C47) -> 158958 | D48: =SUM(D6:D47) -> 14282 | E48: =SUM(E6:E47) -> 16296 | F48: =SUM(F6:F47) -> 31885 | G48: =SUM(G6:G47) -> 21303 | H48: =SUM(H6:H47) -> 17335 | I48: =SUM(I6:I47) -> 18060 | J48: =SUM(J6:J47) -> 14057 | ... P48: =SUM(P6:P47) -> 160286 | Q48: =IFERROR(P48/C48,0) -> 1.0083544

Sheet JAGUNG
A1: LAPORAN PRODUKSI JAGUNG 2025
A2: DINAS PERTANIAN KABUPATEN GARUT
A4: NO | B4: KECAMATAN | C4: Target Produksi Jagung Tahun 2025 | D4: HASIL PRODUKSI | P4: TOTAL | Q4: REALISASI
D5: JANUARI | E5: FEBRUARI | F5: MARET | G5: APRIL | H5: MEI | I5: JUNI | J5: JULI | K5: AGUSTUS | L5: SEPTEMBER | M5: OKTOBER | N5: NOVEMBER | O5: DESEMBER
A6: 1 | B6: Cisewu | C6: 3420 | D6: 1382 | E6: 1208 | F6: 616 | G6: 159 | H6: 282 | I6: 397 | J6: 217 | K6: 329 | L6: 276 | P6: =SUM(D6:O6) -> 4866 | Q6: =IFERROR(P6/C6,0) -> 1.422807
A7: 2 | B7: Caringin | C7: 21548 | D7: 1715 | E7: 5317 | F7: 3736 | G7: 1539 | H7: 2181 | I7: 2562 | J7: 2303 | K7: 0 | L7: 110 | P7: =SUM(D7:O7) -> 19463 | Q7: =IFERROR(P7/C7,0) -> 0.90323928
A8: 3 | B8: Talegong | C8: 4464 | D8: 1504 | E8: 1002 | F8: 801 | G8: 109 | H8: 241 | I8: 448 | J8: 166 | K8: 221 | L8: 146 | P8: =SUM(D8:O8) -> 4638 | Q8: =IFERROR(P8/C8,0) -> 1.0389785
A9: 4 | B9: Bungbulang | C9: 22058 | D9: 323 | E9: 4567 | F9: 3446 | G9: 740 | H9: 1767 | I9: 1803 | J9: 967 | K9: 1622 | L9: 1373 | P9: =SUM(D9:O9) -> 16608 | Q9: =IFERROR(P9/C9,0) -> 0.75292411
A10: 5 | B10: Mekar Mukti | C10: 21668 | D10: 2211 | E10: 5853 | F10: 2221 | G10: 1959 | H10: 2196 | I10: 2867 | J10: 2200 | K10: 0 | L10: 150 | P10: =SUM(D10:O10) -> 19657 | Q10: =IFERROR(P10/C10,0) -> 0.90719033
A11: 6 | B11: Pakenjeng | C11: 21752 | D11: 0 | E11: 6924 | F11: 286 | G11: 1928 | H11: 2203 | I11: 3285 | J11: 2079 | K11: 0 | L11: 1899 | P11: =SUM(D11:O11) -> 18604 | Q11: =IFERROR(P11/C11,0) -> 0.85527768
A12: 7 | B12: Pamulihan | C12: 535 | D12: 0 | E12: 0 | F12: 227 | G12: 378 | H12: 0 | I12: 0 | J12: 66 | K12: 91 | L12: 88 | P12: =SUM(D12:O12) -> 850 | Q12: =IFERROR(P12/C12,0) -> 1.588785
A13: 8 | B13: Cikelet | C13: 15667 | D13: 3530 | E13: 2883 | F13: 1801 | G13: 3307 | H13: 1562 | I13: 2007 | J13: 2044 | K13: 996 | L13: 807 | P13: =SUM(D13:O13) -> 18937 | Q13: =IFERROR(P13/C13,0) -> 1.208719
A14: 9 | B14: Pameungpeuk | C14: 5024 | D14: 128 | E14: 161 | F14: 1264 | G14: 126 | H14: 391 | I14: 694 | J14: 644 | K14: 416 | L14: 373 | P14: =SUM(D14:O14) -> 4197 | Q14: =IFERROR(P14/C14,0) -> 0.83539013
A15: 10 | B15: Cibalong | C15: 13231 | D15: 1412 | E15: 804 | F15: 1928 | G15: 1551 | H15: 1311 | I15: 1665 | J15: 1036 | K15: 695 | L15: 1735 | P15: =SUM(D15:O15) -> 12137 | Q15: =IFERROR(P15/C15,0) -> 0.9173154
A16: 11 | B16: Cisompet | C16: 10040 | D16: 38 | E16: 37 | F16: 377 | G16: 0 | H16: 0 | I16: 0 | J16: 0 | K16: 183 | L16: 206 | P16: =SUM(D16:O16) -> 841 | Q16: =IFERROR(P16/C16,0) -> 0.08376494
A17: 12 | B17: Singajaya | C17: 4276 | D17: 478 | E17: 444 | F17: 383 | G17: 369 | H17: 427 | I17: 498 | J17: 325 | K17: 431 | L17: 140 | P17: =SUM(D17:O17) -> 3495 | Q17: =IFERROR(P17/C17,0) -> 0.81735267
... A47: 42 | B47: Selaawi | C47: 16942 | D47: 38 | E47: 5745 | F47: 4215 | G47: 808 | H47: 1090 | I47: 1898 | J47: 2536 | K47: 1238 | L47: 0 | P47: =SUM(D47:O47) -> 17568 | Q47: =IFERROR(P47/C47,0) -> 1.0369496
A48: JUMLAH | C48: =SUM(C6:C47) -> 521662 | D48: =SUM(D6:D47) -> 35882 | E48: =SUM(E6:E47) -> 96245 | F48: =SUM(F6:F47) -> 83952 | G48: =SUM(G6:G47) -> 36270 | H48: =SUM(H6:H47) -> 43953 | I48: =SUM(I6:I47) -> 59041 | J48: =SUM(J6:J47) -> 45368 | ... P48: =SUM(P6:P47) -> 437500 | Q48: =IFERROR(P48/C48,0) -> 0.83866565

Sheet BAWANG MERAH
A1: LAPORAN PRODUKSI BAWANG MERAH 2025
A2: DINAS PERTANIAN KABUPATEN GARUT
A4: NO | B4: KECAMATAN | C4: Target Produksi Bawang Merah Tahun 2025 | D4: HASIL PRODUKSI | P4: TOTAL | Q4: REALISASI
D5: JANUARI | E5: FEBRUARI | F5: MARET | G5: APRIL | H5: MEI | I5: JUNI | J5: JULI | K5: AGUSTUS | L5: SEPTEMBER | M5: OKTOBER | N5: NOVEMBER | O5: DESEMBER
A6: 1 | B6: Cisewu | C6: 62 | D6: 0 | E6: 0 | F6: 10 | G6: 10 | H6: 10 | I6: 10 | J6: 0 | K6: 0 | L6: 0 | P6: =SUM(D6:O6) -> 40 | Q6: =IFERROR(P6/C6,0) -> 0.64516129
A7: 2 | B7: Caringin | C7: 53 | D7: 30 | E7: 0 | F7: 0 | G7: 10 | H7: 10 | I7: 10 | J7: 10 | K7: 0 | L7: 0 | P7: =SUM(D7:O7) -> 70 | Q7: =IFERROR(P7/C7,0) -> 1.3207547
A8: 3 | B8: Talegong | C8: 0 | D8: 0 | E8: 0 | F8: 0 | G8: 0 | H8: 0 | I8: 0 | J8: 0 | K8: 0 | L8: 0 | P8: =SUM(D8:O8) -> 0 | Q8: =IFERROR(P8/C8,0) -> 0
A9: 4 | B9: Bungbulang | C9: 53 | D9: 0 | E9: 0 | F9: 0 | G9: 0 | H9: 0 | I9: 0 | J9: 0 | K9: 0 | L9: 0 | P9: =SUM(D9:O9) -> 0 | Q9: =IFERROR(P9/C9,0) -> 0
A10: 5 | B10: Mekar Mukti | C10: 36 | D10: 20 | E10: 0 | F10: 0 | G10: 0 | H10: 10 | I10: 20 | J10: 10 | K10: 10 | L10: 10 | P10: =SUM(D10:O10) -> 80 | Q10: =IFERROR(P10/C10,0) -> 2.2222222
A11: 6 | B11: Pakenjeng | C11: 169 | D11: 0 | E11: 20 | F11: 0 | G11: 21 | H11: 31 | I11: 30 | J11: 10 | K11: 10 | L11: 10 | P11: =SUM(D11:O11) -> 132 | Q11: =IFERROR(P11/C11,0) -> 0.78106509
A12: 7 | B12: Pamulihan | C12: 0 | D12: 70 | E12: 100 | F12: 189 | G12: 0 | H12: 0 | I12: 0 | J12: 0 | K12: 0 | L12: 0 | P12: =SUM(D12:O12) -> 359 | Q12: =IFERROR(P12/C12,0) -> 0
A13: 8 | B13: Cikelet | C13: 0 | D13: 0 | E13: 0 | F13: 0 | G13: 0 | H13: 0 | I13: 0 | J13: 0 | K13: 0 | L13: 0 | P13: =SUM(D13:O13) -> 0 | Q13: =IFERROR(P13/C13,0) -> 0
A14: 9 | B14: Pameungpeuk | C14: 0 | D14: 0 | E14: 0 | F14: 889 | G14: 0 | H14: 10 | I14: 0 | J14: 0 | K14: 0 | L14: 0 | P14: =SUM(D14:O14) -> 899 | Q14: =IFERROR(P14/C14,0) -> 0
A15: 10 | B15: Cibalong | C15: 0 | D15: 0 | E15: 0 | F15: 0 | G15: 0 | H15: 0 | I15: 0 | J15: 0 | K15: 0 | L15: 0 | P15: =SUM(D15:O15) -> 0 | Q15: =IFERROR(P15/C15,0) -> 0
A16: 11 | B16: Cisompet | C16: 0 | D16: 0 | E16: 0 | F16: 0 | G16: 0 | H16: 0 | I16: 0 | J16: 0 | K16: 0 | L16: 0 | P16: =SUM(D16:O16) -> 0 | Q16: =IFERROR(P16/C16,0) -> 0
A17: 12 | B17: Singajaya | C17: 0 | D17: 0 | E17: 0 | F17: 0 | G17: 0 | H17: 0 | I17: 0 | J17: 0 | K17: 0 | L17: 0 | P17: =SUM(D17:O17) -> 0 | Q17: =IFERROR(P17/C17,0) -> 0
... A47: 42 | B47: Selaawi | C47: 142 | D47: 0 | E47: 58 | F47: 20 | G47: 10 | H47: 10 | I47: 0 | J47: 20 | K47: 10 | L47: 10 | P47: =SUM(D47:O47) -> 138 | Q47: =IFERROR(P47/C47,0) -> 0.97183099
A48: JUMLAH | C48: =SUM(C6:C47) -> 30638 | D48: =SUM(D6:D47) -> 1737 | E48: =SUM(E6:E47) -> 5772 | F48: =SUM(F6:F47) -> 6865 | G48: =SUM(G6:G47) -> 5797 | H48: =SUM(H6:H47) -> 5607 | I48: =SUM(I6:I47) -> 4179 | J48: =SUM(J6:J47) -> 2616 | ... P48: =SUM(P6:P47) -> 36558 | Q48: =IFERROR(P48/C48,0) -> 1.1932241

Sheet JAHE
A1: LAPORAN PRODUKSI JAHE 2025
A2: DINAS PERTANIAN KABUPATEN GARUT
A4: NO | B4: KECAMATAN | C4: Target Produksi Jahe Tahun 2025 | D4: HASIL PRODUKSI | P4: TOTAL | Q4: REALISASI
D5: JANUARI | E5: FEBRUARI | F5: MARET | G5: APRIL | H5: MEI | I5: JUNI | J5: JULI | K5: AGUSTUS | L5: SEPTEMBER | M5: OKTOBER | N5: NOVEMBER | O5: DESEMBER
A6: 1 | B6: Cisewu | C6: 3420 | D6: 0 | E6: 0 | F6: 0 | G6: 0 | H6: 0 | I6: 0 | J6: 0 | K6: 0 | L6: 3118.5 | P6: =SUM(D6:O6) -> 3118.5 | Q6: =IFERROR(P6/C6,0) -> 0.91184211 | S6: =SUM(G6:I6) -> 0
A7: 2 | B7: Caringin | C7: 61 | D7: 0 | E7: 0 | F7: 0 | G7: 0 | H7: 0 | I7: 0 | J7: 0 | K7: 0 | L7: 0.28 | P7: =SUM(D7:O7) -> 0.28 | Q7: =IFERROR(P7/C7,0) -> 0.0045901639 | S7: =SUM(G7:I7) -> 0
A8: 3 | B8: Talegong | C8: 1661 | D8: 0 | E8: 0 | F8: 0 | G8: 0 | H8: 0 | I8: 0 | J8: 0 | K8: 0 | L8: 2913.57 | P8: =SUM(D8:O8) -> 2913.57 | Q8: =IFERROR(P8/C8,0) -> 1.754106 | S8: =SUM(G8:I8) -> 0
A9: 4 | B9: Bungbulang | C9: 209 | D9: 0 | E9: 0 | F9: 0 | G9: 0 | H9: 0 | I9: 95.04 | J9: 0 | K9: 0 | L9: 0 | P9: =SUM(D9:O9) -> 95.04 | Q9: =IFERROR(P9/C9,0) -> 0.45473684 | S9: =SUM(G9:I9) -> 95.04
A10: 5 | B10: Mekar Mukti | C10: 62 | D10: 0 | E10: 0 | F10: 0 | G10: 0 | H10: 0 | I10: 4 | J10: 0 | K10: 0 | L10: 23.2 | P10: =SUM(D10:O10) -> 27.2 | Q10: =IFERROR(P10/C10,0) -> 0.43870968 | S10: =SUM(G10:I10) -> 4
A11: 6 | B11: Pakenjeng | C11: 84 | D11: 0 | E11: 0 | F11: 0 | G11: 0 | H11: 0 | I11: 0 | J11: 0 | K11: 0 | L11: 0 | P11: =SUM(D11:O11) -> 0 | Q11: =IFERROR(P11/C11,0) -> 0 | S11: =SUM(G11:I11) -> 0
A12: 7 | B12: Pamulihan | C12: 21 | D12: 0 | E12: 0 | F12: 0 | G12: 0 | H12: 0 | I12: 0 | J12: 0 | K12: 0 | L12: 0 | P12: =SUM(D12:O12) -> 0 | Q12: =IFERROR(P12/C12,0) -> 0 | S12: =SUM(G12:I12) -> 0
A13: 8 | B13: Cikelet | C13: 4 | D13: 0 | E13: 0 | F13: 0 | G13: 0 | H13: 0 | I13: 0 | J13: 0 | K13: 0 | L13: 0 | P13: =SUM(D13:O13) -> 0 | Q13: =IFERROR(P13/C13,0) -> 0 | S13: =SUM(G13:I13) -> 0
A14: 9 | B14: Pameungpeuk | C14: 0 | D14: 0 | E14: 0 | F14: 0 | G14: 0 | H14: 0 | I14: 0 | J14: 0 | K14: 0 | L14: 0 | P14: =SUM(D14:O14) -> 0 | Q14: =IFERROR(P14/C14,0) -> 0 | S14: =SUM(G14:I14) -> 0
A15: 10 | B15: Cibalong | C15: 23 | D15: 0 | E15: 0 | F15: 0 | G15: 0 | H15: 0 | I15: 0 | J15: 0 | K15: 0 | L15: 0 | P15: =SUM(D15:O15) -> 0 | Q15: =IFERROR(P15/C15,0) -> 0 | S15: =SUM(G15:I15) -> 0
A16: 11 | B16: Cisompet | C16: 115 | D16: 0 | E16: 0 | F16: 0 | G16: 0 | H16: 0 | I16: 0 | J16: 0 | K16: 0 | L16: 0 | P16: =SUM(D16:O16) -> 0 | Q16: =IFERROR(P16/C16,0) -> 0 | S16: =SUM(G16:I16) -> 0
A17: 12 | B17: Singajaya | C17: 39 | D17: 0 | E17: 0 | F17: 0 | G17: 0 | H17: 0 | I17: 15.81 | J17: 0 | K17: 0 | L17: 0 | P17: =SUM(D17:O17) -> 15.81 | Q17: =IFERROR(P17/C17,0) -> 0.40538462 | S17: =SUM(G17:I17) -> 15.81
... A47: 42 | B47: Selaawi | C47: 433 | D47: 0 | E47: 0 | F47: 0 | G47: 0 | H47: 0 | I47: 0 | J47: 0 | K47: 0 | L47: 594 | P47: =SUM(D47:O47) -> 594 | Q47: =IFERROR(P47/C47,0) -> 1.3718245 | S47: =SUM(G47:I47) -> 0
A48: JUMLAH | C48: =SUM(C6:C47) -> 7410 | D48: =SUM(D6:D47) -> 0 | E48: =SUM(E6:E47) -> 0 | F48: =SUM(F6:F47) -> 28.32 | G48: =SUM(G6:G47) -> 0 | H48: =SUM(H6:H47) -> 0 | I48: =SUM(I6:I47) -> 743.65 | J48: =SUM(J6:J47) -> 0 | ... P48: =SUM(P6:P47) -> 12037.09 | Q48: =P48/C48 -> 1.6244386 | S48: =SUM(G48:I48) -> 743.65

Sheet KENTANG
A1: LAPORAN PRODUKSI KENTANG 2025
A2: DINAS PERTANIAN KABUPATEN GARUT
A4: NO | B4: KECAMATAN | C4: Target Produksi Kentang Tahun 2025 | D4: HASIL PRODUKSI | P4: TOTAL | Q4: REALISASI
D5: JANUARI | E5: FEBRUARI | F5: MARET | G5: APRIL | H5: MEI | I5: JUNI | J5: JULI | K5: AGUSTUS | L5: SEPTEMBER | M5: OKTOBER | N5: NOVEMBER | O5: DESEMBER
A6: 1 | B6: Cisewu | C6: 0 | D6: 0 | E6: 0 | F6: 0 | G6: 0 | H6: 0 | I6: 0 | J6: 0 | K6: 0 | L6: 0 | P6: =SUM(D6:N6) -> 0 | Q6: - | S6: =IFERROR(L6*$L$52/100,0) -> 0
A7: 2 | B7: Caringin | C7: 0 | D7: 0 | E7: 0 | F7: 0 | G7: 0 | H7: 0 | I7: 0 | J7: 0 | K7: 0 | L7: 0 | P7: =SUM(D7:N7) -> 0 | Q7: - | S7: =IFERROR(L7*$L$52/100,0) -> 0
A8: 3 | B8: Talegong | C8: 471 | D8: 70.3 | E8: 0 | F8: 199 | G8: 57 | H8: 0 | I8: 0 | J8: 0 | K8: 0 | L8: 0 | P8: =SUM(D8:N8) -> 326.3 | Q8: =P8/C8 -> 0.69278132 | S8: =IFERROR(L8*$L$52/100,0) -> 0
A9: 4 | B9: Bungbulang | C9: 0 | D9: 0 | E9: 0 | F9: 0 | G9: 0 | H9: 0 | I9: 0 | J9: 0 | K9: 0 | L9: 0 | P9: =SUM(D9:N9) -> 0 | Q9: - | S9: =IFERROR(L9*$L$52/100,0) -> 0
A10: 5 | B10: Mekar Mukti | C10: 0 | D10: 0 | E10: 0 | F10: 0 | G10: 0 | H10: 0 | I10: 0 | J10: 0 | K10: 0 | L10: 0 | P10: =SUM(D10:N10) -> 0 | Q10: - | S10: =IFERROR(L10*$L$52/100,0) -> 0
A11: 6 | B11: Pakenjeng | C11: 0 | D11: 0 | E11: 2567 | F11: 4062 | G11: 0 | H11: 0 | I11: 0 | J11: 0 | K11: 0 | L11: 0 | P11: =SUM(D11:N11) -> 6629 | Q11: - | S11: =IFERROR(L11*$L$52/100,0) -> 0
A12: 7 | B12: Pamulihan | C12: 5855 | D12: 468.2 | E12: 2411 | F12: 2275 | G12: 567 | H12: 470 | I12: 762 | J12: 235 | K12: 188 | L12: 258 | P12: =SUM(D12:O12) -> 7634.2 | Q12: =P12/C12 -> 1.303877 | S12: =IFERROR(L12*$L$52/100,0) -> 0
A13: 8 | B13: Cikelet | C13: 0 | D13: 0 | E13: 0 | F13: 0 | G13: 0 | H13: 0 | I13: 0 | J13: 0 | K13: 0 | L13: 0 | P13: =SUM(D13:O13) -> 0 | Q13: - | S13: =IFERROR(L13*$L$52/100,0) -> 0
A14: 9 | B14: Pameungpeuk | C14: 0 | D14: 0 | E14: 0 | F14: 0 | G14: 0 | H14: 0 | I14: 0 | J14: 0 | K14: 0 | L14: 0 | P14: =SUM(D14:O14) -> 0 | Q14: - | S14: =IFERROR(L14*$L$52/100,0) -> 0
A15: 10 | B15: Cibalong | C15: 0 | D15: 0 | E15: 0 | F15: 0 | G15: 0 | H15: 0 | I15: 0 | J15: 0 | K15: 0 | L15: 0 | P15: =SUM(D15:O15) -> 0 | Q15: - | S15: =IFERROR(L15*$L$52/100,0) -> 0
A16: 11 | B16: Cisompet | C16: 0 | D16: 0 | E16: 0 | F16: 0 | G16: 0 | H16: 0 | I16: 0 | J16: 0 | K16: 0 | L16: 0 | P16: =SUM(D16:O16) -> 0 | Q16: - | S16: =IFERROR(L16*$L$52/100,0) -> 0
A17: 12 | B17: Singajaya | C17: 0 | D17: 0 | E17: 0 | F17: 0 | G17: 0 | H17: 0 | I17: 0 | J17: 0 | K17: 0 | L17: 0 | P17: =SUM(D17:O17) -> 0 | Q17: - | S17: =IFERROR(L17*$L$52/100,0) -> 0
A18: 13 | B18: Cihurip | C18: 0 | D18: 0 | E18: 0 | F18: 0 | G18: 0 | H18: 0 | I18: 0 | J18: 0 | K18: 0 | L18: 0 | P18: =SUM(D18:O18) -> 0 | Q18: - | S18: =IFERROR(L18*$L$52/100,0) -> 0
A19: 14 | B19: Peundeuy | C19: 0 | D19: 0 | E19: 0 | F19: 0 | G19: 0 | H19: 0 | I19: 0 | J19: 0 | K19: 0 | L19: 0 | P19: =SUM(D19:O19) -> 0 | Q19: - | S19: =IFERROR(L19*$L$52/100,0) -> 0
A20: 15 | B20: Cikajang | C20: 40273 | D20: 2599.6 | E20: 2750 | F20: 4317 | G20: 8843 | H20: 5163 | I20: 4546 | J20: 3873 | K20: 3169 | L20: 2582 | P20: =SUM(D20:O20) -> 37842.6 | Q20: =P20/C20 -> 0.93965188 | S20: =IFERROR(L20*$L$52/100,0) -> 0
A21: 16 | B21: Banjarwangi | C21: 4625 | D21: 492 | E21: 351 | F21: 511 | G21: 284 | H21: 329 | I21: 517 | J21: 423 | K21: 282 | L21: 282 | P21: =SUM(D21:O21) -> 3471 | Q21: =P21/C21 -> 0.75048649 | S21: =IFERROR(L21*$L$52/100,0) -> 0
A22: 17 | B22: Cilawu | C22: 6091 | D22: 0 | E22: 118 | F22: 95 | G22: 95 | H22: 142 | I22: 189 | J22: 166 | K22: 51 | L22: 47 | P22: =SUM(D22:O22) -> 903 | Q22: =P22/C22 -> 0.14825152 | S22: =IFERROR(L22*$L$52/100,0) -> 0
A23: 18 | B23: Bayongbong | C23: 4574 | D23: 188.7 | E23: 802 | F23: 728 | G23: 260 | H23: 212 | I23: 543 | J23: 401 | K23: 307 | L23: 0 | P23: =SUM(D23:O23) -> 3441.7 | Q23: =P23/C23 -> 0.75244862 | S23: =IFERROR(L23*$L$52/100,0) -> 0
A24: 19 | B24: Cigedug | C24: 21068 | D24: 2311 | E24: 2547 | F24: 2807 | G24: 2007 | H24: 2035 | I24: 2148 | J24: 1840 | K24: 1699 | L24: 991 | P24: =SUM(D24:O24) -> 18385 | Q24: =P24/C24 -> 0.87265047 | S24: =IFERROR(L24*$L$52/100,0) -> 0
A25: 20 | B25: Cisurupan | C25: 27681 | D25: 2575 | E25: 3047 | F25: 2843 | G25: 3089 | H25: 3638 | I25: 3145 | J25: 2700 | K25: 2183 | L25: 1878 | P25: =SUM(D25:O25) -> 25098 | Q25: =P25/C25 -> 0.9066869 | S25: =IFERROR(L25*$L$52/100,0) -> 0
A26: 21 | B26: Sukaresmi | C26: 15657 | D26: 916.5 | E26: 2304 | F26: 1393 | G26: 1755 | H26: 2332 | I26: 1744 | J26: 2089 | K26: 1103 | L26: 963 | P26: =SUM(D26:O26) -> 14599.5 | Q26: =P26/C26 -> 0.93245833 | S26: =IFERROR(L26*$L$52/100,0) -> 0
A27: 22 | B27: Samarang | C27: 3085 | D27: 44 | E27: 71 | F27: 227 | G27: 312 | H27: 375 | I27: 422 | J27: 329 | K27: 352 | L27: 188 | P27: =SUM(D27:O27) -> 2320 | Q27: =P27/C27 -> 0.75202593 | S27: =IFERROR(L27*$L$52/100,0) -> 0
A28: 23 | B28: Pasir Wangi | C28: 52748 | D28: 1610 | E28: 2585 | F28: 2468 | G28: 4085 | H28: 2019 | I28: 5896 | J28: 4882 | K28: 4037 | L28: 3216 | P28: =SUM(D28:O28) -> 30798 | Q28: =P28/C28 -> 0.58387048 | S28: =IFERROR(L28*$L$52/100,0) -> 0
A29: 24 | B29: Tarogong Kaler | C29: 0 | D29: 0 | E29: 0 | F29: 0 | G29: 0 | H29: 0 | I29: 0 | J29: 0 | K29: 0 | L29: 0 | P29: =SUM(D29:O29) -> 0 | Q29: - | S29: =IFERROR(L29*$L$52/100,0) -> 0
A30: 25 | B30: Tarogong Kidul | C30: 0 | D30: 0 | E30: 0 | F30: 0 | G30: 0 | H30: 0 | I30: 0 | J30: 0 | K30: 0 | L30: 0 | P30: =SUM(D30:O30) -> 0 | Q30: - | S30: =IFERROR(L30*$L$52/100,0) -> 0
A31: 26 | B31: Garut Kota | C31: 0 | D31: 0 | E31: 0 | F31: 0 | G31: 0 | H31: 0 | I31: 0 | J31: 0 | K31: 0 | L31: 0 | P31: =SUM(D31:O31) -> 0 | Q31: - | S31: =IFERROR(L31*$L$52/100,0) -> 0
A32: 27 | B32: Karangpawitan | C32: 1098 | D32: 0 | E32: 71 | F32: 46 | G32: 142 | H32: 141 | I32: 172 | J32: 94 | K32: 94 | L32: 117 | P32: =SUM(D32:O32) -> 877 | Q32: =P32/C32 -> 0.79872495 | S32: =IFERROR(L32*$L$52/100,0) -> 0
A33: 28 | B33: Wanaraja | C33: 1568 | D33: 0 | E33: 470 | F33: 0 | G33: 284 | H33: 235 | I33: 492 | J33: 47 | K33: 71 | L33: 0 | P33: =SUM(D33:O33) -> 1599 | Q33: =P33/C33 -> 1.0197704 | S33: =IFERROR(L33*$L$52/100,0) -> 0
A34: 29 | B34: Pangatikan | C34: 496 | D34: 0 | E34: 51 | F34: 45 | G34: 57 | H34: 0 | I34: 25 | J34: 0 | K34: 0 | L34: 24 | P34: =SUM(D34:O34) -> 202 | Q34: =P34/C34 -> 0.40725806 | S34: =IFERROR(L34*$L$52/100,0) -> 0
A35: 30 | B35: Sucinaraja | C35: 2222 | D35: 116.5 | E35: 0 | F35: 0 | G35: 0 | H35: 282 | I35: 246 | J35: 211 | K35: 0 | L35: 141 | P35: =SUM(D35:O35) -> 996.5 | Q35: =P35/C35 -> 0.44846985 | S35: =IFERROR(L35*$L$52/100,0) -> 0
A36: 31 | B36: Sukawening | C36: 0 | D36: 0 | E36: 0 | F36: 0 | G36: 0 | H36: 0 | I36: 0 | J36: 0 | K36: 46 | L36: 0 | P36: =SUM(D36:O36) -> 46 | Q36: - | S36: =IFERROR(L36*$L$52/100,0) -> 0
A37: 32 | B37: Karang Tengah | C37: 392 | D37: 0 | E37: 23 | F37: 57 | G37: 29 | H37: 0 | I37: 0 | J37: 0 | K37: 0 | L37: 24 | P37: =SUM(D37:O37) -> 133 | Q37: =P37/C37 -> 0.33928571 | S37: =IFERROR(L37*$L$52/100,0) -> 0
A38: 33 | B38: Banyuresmi | C38: 0 | D38: 0 | E38: 0 | F38: 0 | G38: 0 | H38: 0 | I38: 0 | J38: 0 | K38: 0 | L38: 0 | P38: =SUM(D38:O38) -> 0 | Q38: - | S38: =IFERROR(L38*$L$52/100,0) -> 0
A39: 34 | B39: Leles | C39: 2248 | D39: 70.5 | E39: 141 | F39: 353 | G39: 212 | H39: 282 | I39: 230 | J39: 212 | K39: 0 | L39: 805 | P39: =SUM(D39:O39) -> 2305.5 | Q39: =P39/C39 -> 1.0255783 | S39: =IFERROR(L39*$L$52/100,0) -> 0
A40: 35 | B40: Leuwigoong | C40: 0 | D40: 0 | E40: 0 | F40: 0 | G40: 0 | H40: 0 | I40: 0 | J40: 0 | K40: 0 | L40: 0 | P40: =SUM(D40:O40) -> 0 | Q40: - | S40: =IFERROR(L40*$L$52/100,0) -> 0
A41: 36 | B41: Kadungora | C41: 575 | D41: 0 | E41: 0 | F41: 0 | G41: 0 | H41: 0 | I41: 0 | J41: 0 | K41: 0 | L41: 0 | P41: =SUM(D41:O41) -> 0 | Q41: =P41/C41 -> 0 | S41: =IFERROR(L41*$L$52/100,0) -> 0
...

Sheet JERUK
A1: LAPORAN PRODUKSI JERUK 2025
A2: DINAS PERTANIAN KABUPATEN GARUT
A4: NO | B4: KECAMATAN | C4: Target Produksi Kentang Tahun 2025 | D4: HASIL PRODUKSI | P4: TOTAL | Q4: REALISASI
D5: JANUARI | E5: FEBRUARI | F5: MARET | G5: APRIL | H5: MEI | I5: JUNI | J5: JULI | K5: AGUSTUS | L5: SEPTEMBER | M5: OKTOBER | N5: NOVEMBER | O5: DESEMBER
A6: 1 | B6: Cisewu | C6: 72 | D6: 0 | E6: 0 | F6: 5 | G6: 0 | H6: 0 | I6: 25 | J6: 0 | K6: 0 | L6: 15 | P6: =SUM(D6:O6) -> 45 | Q6: =P6/C6 -> 0.625
A7: 2 | B7: Caringin | C7: 73 | D7: 0 | E7: 0 | F7: 7 | G7: 0 | H7: 0 | I7: 31 | J7: 0 | K7: 0 | L7: 19 | P7: =SUM(D7:O7) -> 57 | Q7: =P7/C7 -> 0.78082192
A8: 3 | B8: Talegong | C8: 21 | D8: 0 | E8: 0 | F8: 0 | G8: 0 | H8: 0 | I8: 0 | J8: 0 | K8: 0 | L8: 0 | P8: =SUM(D8:O8) -> 0 | Q8: =P8/C8 -> 0
A9: 4 | B9: Bungbulang | C9: 60 | D9: 0 | E9: 0 | F9: 0 | G9: 0 | H9: 0 | I9: 0 | J9: 0 | K9: 0 | L9: 0 | P9: =SUM(D9:O9) -> 0 | Q9: =P9/C9 -> 0
A10: 5 | B10: Mekar Mukti | C10: 38 | D10: 0 | E10: 0 | F10: 6 | G10: 0 | H10: 0 | I10: 28 | J10: 0 | K10: 0 | L10: 15 | P10: =SUM(D10:O10) -> 49 | Q10: =P10/C10 -> 1.2894737
A11: 6 | B11: Pakenjeng | C11: 296 | D11: 0 | E11: 0 | F11: 37 | G11: 0 | H11: 0 | I11: 11 | J11: 0 | K11: 0 | L11: 30 | P11: =SUM(D11:O11) -> 78 | Q11: =P11/C11 -> 0.26351351
A12: 7 | B12: Pamulihan | C12: 46 | D12: 0 | E12: 0 | F12: 4 | G12: 0 | H12: 0 | I12: 19 | J12: 0 | K12: 0 | L12: 11 | P12: =SUM(D12:O12) -> 34 | Q12: =P12/C12 -> 0.73913043
A13: 8 | B13: Cikelet | C13: 166 | D13: 0 | E13: 0 | F13: 20 | G13: 0 | H13: 0 | I13: 91 | J13: 0 | K13: 0 | L13: 0 | P13: =SUM(D13:O13) -> 111 | Q13: =P13/C13 -> 0.6686747
A14: 9 | B14: Pameungpeuk | C14: 37 | D14: 0 | E14: 0 | F14: 3 | G14: 0 | H14: 0 | I14: 15 | J14: 0 | K14: 0 | L14: 9 | P14: =SUM(D14:O14) -> 27 | Q14: =P14/C14 -> 0.72972973
A15: 10 | B15: Cibalong | C15: 263 | D15: 0 | E15: 0 | F15: 0 | G15: 0 | H15: 0 | I15: 0 | J15: 0 | K15: 0 | L15: 0 | P15: =SUM(D15:O15) -> 0 | Q15: =P15/C15 -> 0
A16: 11 | B16: Cisompet | C16: 106 | D16: 0 | E16: 0 | F16: 12 | G16: 0 | H16: 0 | I16: 57 | J16: 0 | K16: 0 | L16: 31 | P16: =SUM(D16:O16) -> 100 | Q16: =P16/C16 -> 0.94339623
A17: 12 | B17: Singajaya | C17: 19 | D17: 0 | E17: 0 | F17: 3 | G17: 0 | H17: 0 | I17: 13 | J17: 0 | K17: 0 | L17: 7 | P17: =SUM(D17:O17) -> 23 | Q17: =P17/C17 -> 1.2105263
... A39: 34 | B39: Leles | C39: 52 | D39: 0 | E39: 0 | F39: 8 | G39: 0 | H39: 0 | I39: 12 | J39: 0 | K39: 0 | L39: 21 | P39: =SUM(D39:O39) -> 41 | Q39: =P39/C39 -> 0.78846154
A40: 35 | B40: Leuwigoong | C40: 0 | D40: 0 | E40: 0 | F40: 2 | G40: 0 | H40: 0 | I40: 7 | J40: 0 | K40: 0 | L40: 5 | P40: =SUM(D40:O40) -> 14 | Q40: -
A41: 36 | B41: Kadungora | C41: 194 | D41: 0 | E41: 0 | F41: 18 | G41: 0 | H41: 0 | I41: 85 | J41: 0 | K41: 0 | L41: 53 | P41: =SUM(D41:O41) -> 156 | Q41: =P41/C41 -> 0.80412371
A42: 37 | B42: Cibiuk | C42: 92 | D42: 0 | E42: 0 | F42: 6 | G42: 0 | H42: 0 | I42: 26 | J42: 0 | K42: 0 | L42: 17 | P42: =SUM(D42:O42) -> 49 | Q42: =P42/C42 -> 0.5326087
A43: 38 | B43: Cibatu | C43: 35 | D43: 0 | E43: 0 | F43: 3 | G43: 0 | H43: 0 | I43: 13 | J43: 0 | K43: 0 | L43: 7 | P43: =SUM(D43:O43) -> 23 | Q43: =P43/C43 -> 0.65714286
A44: 39 | B44: Kersamanah | C44: 75 | D44: 0 | E44: 0 | F44: 2 | G44: 0 | H44: 0 | I44: 10 | J44: 0 | K44: 0 | L44: 7 | P44: =SUM(D44:O44) -> 19 | Q44: =P44/C44 -> 0.25333333
A45: 40 | B45: Malangbong | C45: 257 | D45: 0 | E45: 0 | F45: 20 | G45: 0 | H45: 0 | I45: 95 | J45: 0 | K45: 0 | L45: 0 | P45: =SUM(D45:O45) -> 115 | Q45: =P45/C45 -> 0.44747082
A46: 41 | B46: Limbangan | C46: 127 | D46: 0 | E46: 0 | F46: 6 | G46: 0 | H46: 0 | I46: 26 | J46: 0 | K46: 0 | L46: 16 | P46: =SUM(D46:O46) -> 48 | Q46: =P46/C46 -> 0.37795276
A47: 42 | B47: Selaawi | C47: 1 | D47: 0 | E47: 0 | F47: 0 | G47: 0 | H47: 0 | I47: 0 | J47: 0 | K47: 0 | L47: 0 | P47: =SUM(D47:O47) -> 0 | Q47: =P47/C47 -> 0
A48: JUMLAH | C48: =SUM(C6:C47) -> 13742 | D48: =SUM(D6:D47) -> 0 | E48: =SUM(E6:E47) -> 0 | F48: =SUM(F6:F47) -> 1028 | G48: =SUM(G6:G47) -> 0 | H48: =SUM(H6:H47) -> 0 | I48: =SUM(I6:I47) -> 4310 | J48: =SUM(J6:J47) -> 0 | ... M48: =SUM(M6:M47) -> 0 | O48: =SUM(O6:O47) -> 0 | P48: =SUM(P6:P47) -> 7699 | Q48: =P48/C48 -> 0.56025324

Sheet TEH
A1: LAPORAN PRODUKSI TEH 2025
A2: DINAS PERTANIAN KABUPATEN GARUT
A4: NO | B4: KECAMATAN | C4: Target Produksi Teh Tahun 2025 | D4: HASIL PRODUKSI | P4: TOTAL | Q4: REALISASI
D5: JANUARI | E5: FEBRUARI | F5: MARET | G5: APRIL | H5: MEI | I5: JUNI | J5: JULI | K5: AGUSTUS | L5: SEPTEMBER | M5: OKTOBER | N5: NOVEMBER | O5: DESEMBER
A6: 1 | B6: Cisewu | C6: 170 | D6: 2.71765 | E6: 6.16235 | F6: 5.55 | G6: 5.55 | H6: 5.18 | I6: 3.33 | J6: 2.59 | K6: 2.22 | L6: 1.11 | P6: =SUM(D6:O6) -> 34.41 | Q6: =P6/C6 -> 0.20241176 | S6: =IF(Q6<70,C6*2.936/100,0) -> 4.9912
A7: 2 | B7: Caringin | C7: 0 | D7: 0 | E7: 0 | F7: 0 | G7: 0 | H7: 0 | I7: 0 | J7: 0 | K7: 0 | L7: 0 | P7: =SUM(D7:O7) -> 0 | Q7: - | S7: =IF(Q7<70,C7*2.936/100,0) -> 0
A8: 3 | B8: Talegong | C8: 92 | D8: 17.99525 | E8: 40.80475 | F8: 36.75 | G8: 36.75 | H8: 34.3 | I8: 22.05 | J8: 17.15 | K8: 14.7 | L8: 7.35 | P8: =SUM(D8:O8) -> 227.85 | Q8: =P8/C8 -> 2.4766304 | S8: =IF(Q8<70,C8*2.936/100,0) -> 2.70112
A9: 4 | B9: Bungbulang | C9: 0 | D9: 0 | E9: 0 | F9: 0 | G9: 0 | H9: 0 | I9: 0 | J9: 0 | K9: 0 | L9: 0 | P9: =SUM(D9:O9) -> 0 | Q9: - | S9: =IF(Q9<70,C9*2.936/100,0) -> 0
A10: 5 | B10: Mekar Mukti | C10: 0 | D10: 0 | E10: 0 | F10: 0 | G10: 0 | H10: 0 | I10: 0 | J10: 0 | K10: 0 | L10: 0 | P10: =SUM(D10:O10) -> 0 | Q10: - | S10: =IF(Q10<70,C10*2.936/100,0) -> 0
A11: 6 | B11: Pakenjeng | C11: 192 | D11: 14.873625 | E11: 33.726375 | F11: 30.375 | G11: 30.375 | H11: 28.35 | I11: 18.225 | J11: 14.175 | K11: 12.15 | L11: 6.075 | P11: =SUM(D11:O11) -> 188.325 | Q11: =P11/C11 -> 0.98085938 | S11: =IF(Q11<70,C11*2.936/100,0) -> 5.63712
A12: 7 | B12: Pamulihan | C12: 188 | D12: 22.9164 | E12: 51.9636 | F12: 46.8 | G12: 46.8 | H12: 43.68 | I12: 28.08 | J12: 21.84 | K12: 18.72 | L12: 9.36 | P12: =SUM(D12:O12) -> 290.16 | Q12: =P12/C12 -> 1.5434043 | S12: =IF(Q12<70,C12*2.936/100,0) -> 5.51968
A13: 8 | B13: Cikelet | C13: 0 | D13: 0 | E13: 0 | F13: 0 | G13: 0 | H13: 0 | I13: 0 | J13: 0 | K13: 0 | L13: 0 | P13: =SUM(D13:O13) -> 0 | Q13: - | S13: =IF(Q13<70,C13*2.936/100,0) -> 0
A14: 9 | B14: Pameungpeuk | C14: 0 | D14: 0 | E14: 0 | F14: 0 | G14: 0 | H14: 0 | I14: 0 | J14: 0 | K14: 0 | L14: 0 | P14: =SUM(D14:O14) -> 0 | Q14: - | S14: =IF(Q14<70,C14*2.936/100,0) -> 0
A15: 10 | B15: Cibalong | C15: 0 | D15: 0 | E15: 0 | F15: 0 | G15: 0 | H15: 0 | I15: 0 | J15: 0 | K15: 0 | L15: 0 | P15: =SUM(D15:O15) -> 0 | Q15: - | S15: =IF(Q15<70,C15*2.936/100,0) -> 0
A16: 11 | B16: Cisompet | C16: 0 | D16: 0 | E16: 0 | F16: 0 | G16: 0 | H16: 0 | I16: 0 | J16: 0 | K16: 0 | L16: 0 | P16: =SUM(D16:O16) -> 0 | Q16: - | S16: =IF(Q16<70,C16*2.936/100,0) -> 0
A17: 12 | B17: Singajaya | C17: 912 | D17: 92.62045 | E17: 210.01955 | F17: 189.15 | G17: 189.15 | H17: 176.54 | I17: 113.49 | J17: 88.27 | K17: 75.66 | L17: 37.83 | P17: =SUM(D17:O17) -> 1172.73 | Q17: =P17/C17 -> 1.2858882 | S17: =IF(Q17<70,C17*2.936/100,0) -> 26.77632
A18: 13 | B18: Cihurip | C18: 22 | D18: 0.386347 | E18: 0.876053 | F18: 0.789 | G18: 0.789 | H18: 0.7364 | I18: 0.4734 | J18: 0.3682 | K18: 0.3156 | L18: 0.1578 | P18: =SUM(D18:O18) -> 4.8918 | Q18: =P18/C18 -> 0.22235455 | S18: =IF(Q18<70,C18*2.936/100,0) -> 0.64592
A19: 14 | B19: Peundeuy | C19: 201 | D19: 13.14755 | E19: 29.81245 | F19: 26.85 | G19: 26.85 | H19: 25.06 | I19: 16.11 | J19: 12.53 | K19: 10.74 | L19: 5.37 | P19: =SUM(D19:O19) -> 166.47 | Q19: =P19/C19 -> 0.82820896 | S19: =IF(Q19<70,C19*2.936/100,0) -> 5.90136
A20: 15 | B20: Cikajang | C20: 611 | D20: 4.3592575 | E20: 9.8847425 | F20: 8.9025 | G20: 8.9025 | H20: 8.309 | I20: 5.3415 | J20: 4.1545 | K20: 3.561 | L20: 1.7805 | P20: =SUM(D20:O20) -> 55.1955 | Q20: =P20/C20 -> 0.090336334 | S20: =IF(Q20<70,C20*2.936/100,0) -> 17.93896
A21: 16 | B21: Banjarwangi | C21: 384 | D21: 11.6051 | E21: 26.3149 | F21: 23.7 | G21: 23.7 | H21: 22.12 | I21: 14.22 | J21: 11.06 | K21: 9.48 | L21: 4.74 | P21: =SUM(D21:O21) -> 146.94 | Q21: =P21/C21 -> 0.38265625 | S21: =IF(Q21<70,C21*2.936/100,0) -> 11.27424
A22: 17 | B22: Cilawu | C22: 109 | D22: 4.518644 | E22: 10.246156 | F22: 9.228 | G22: 9.228 | H22: 8.6128 | I22: 5.5368 | J22: 4.3064 | K22: 3.6912 | L22: 1.8456 | P22: =SUM(D22:O22) -> 57.2136 | Q22: =P22/C22 -> 0.52489541 | S22: =IF(Q22<70,C22*2.936/100,0) -> 3.20024
A23: 18 | B23: Bayongbong | C23: 0 | D23: 0 | E23: 0 | F23: 0 | G23: 0 | H23: 0 | I23: 0 | J23: 0 | K23: 0 | L23: 0 | P23: =SUM(D23:O23) -> 0 | Q23: - | S23: =IF(Q23<70,C23*2.936/100,0) -> 0
A24: 19 | B24: Cigedug | C24: 127 | D24: 5.36185 | E24: 12.15815 | F24: 10.95 | G24: 10.95 | H24: 10.22 | I24: 6.57 | J24: 5.11 | K24: 4.38 | L24: 2.19 | P24: =SUM(D24:O24) -> 67.89 | Q24: =P24/C24 -> 0.53456693 | S24: =IF(Q24<70,C24*2.936/100,0) -> 3.72872
A25: 20 | B25: Cisurupan | C25: 240 | D25: 15.05725 | E25: 34.14275 | F25: 30.75 | G25: 30.75 | H25: 28.7 | I25: 18.45 | J25: 14.35 | K25: 12.3 | L25: 6.15 | P25: =SUM(D25:O25) -> 190.65 | Q25: =P25/C25 -> 0.794375 | S25: =IF(Q25<70,C25*2.936/100,0) -> 7.0464
A26: 21 | B26: Sukaresmi | C26: 0 | D26: 0 | E26: 0 | F26: 0 | G26: 0 | H26: 0 | I26: 0 | J26: 0 | K26: 0 | L26: 0 | P26: =SUM(D26:O26) -> 0 | Q26: - | S26: =IF(Q26<70,C26*2.936/100,0) -> 0
A27: 22 | B27: Samarang | C27: 0 | D27: 0 | E27: 0 | F27: 0 | G27: 0 | H27: 0 | I27: 0 | J27: 0 | K27: 0 | L27: 0 | P27: =SUM(D27:O27) -> 0 | Q27: - | S27: =IF(Q27<70,C27*2.936/100,0) -> 0
A28: 23 | B28: Pasir Wangi | C28: 0 | D28: 0 | E28: 0 | F28: 0 | G28: 0 | H28: 0 | I28: 0 | J28: 0 | K28: 0 | L28: 0 | P28: =SUM(D28:O28) -> 0 | Q28: - | S28: =IF(Q28<70,C28*2.936/100,0) -> 0
A29: 24 | B29: Tarogong Kaler | C29: 0 | D29: 0 | E29: 0 | F29: 0 | G29: 0 | H29: 0 | I29: 0 | J29: 0 | K29: 0 | L29: 0 | P29: =SUM(D29:O29) -> 0 | Q29: - | S29: =IF(Q29<70,C29*2.936/100,0) -> 0
A30: 25 | B30: Tarogong Kidul | C30: 0 | D30: 0 | E30: 0 | F30: 0 | G30: 0 | H30: 0 | I30: 0 | J30: 0 | K30: 0 | L30: 0 | P30: =SUM(D30:O30) -> 0 | Q30: - | S30: =IF(Q30<70,C30*2.936/100,0) -> 0
A31: 26 | B31: Garut Kota | C31: 0 | D31: 0 | E31: 0 | F31: 0 | G31: 0 | H31: 0 | I31: 0 | J31: 0 | K31: 0 | L31: 0 | P31: =SUM(D31:O31) -> 0 | Q31: - | S31: =IF(Q31<70,C31*2.936/100,0) -> 0
A32: 27 | B32: Karangpawitan | C32: 0 | D32: 0 | E32: 0 | F32: 0 | G32: 0 | H32: 0 | I32: 0 | J32: 0 | K32: 0 | L32: 0 | P32: =SUM(D32:O32) -> 0 | Q32: - | S32: =IF(Q32<70,C32*2.936/100,0) -> 0
A33: 28 | B33: Wanaraja | C33: 0 | D33: 0 | E33: 0 | F33: 0 | G33: 0 | H33: 0 | I33: 0 | J33: 0 | K33: 0 | L33: 0 | P33: =SUM(D33:O33) -> 0 | Q33: - | S33: =IF(Q33<70,C33*2.936/100,0) -> 0
A34: 29 | B34: Pangatikan | C34: 0 | D34: 0 | E34: 0 | F34: 0 | G34: 0 | H34: 0 | I34: 0 | J34: 0 | K34: 0 | L34: 0 | P34: =SUM(D34:O34) -> 0 | Q34: - | S34: =IF(Q34<70,C34*2.936/100,0) -> 0
A35: 30 | B35: Sucinaraja | C35: 0 | D35: 0 | E35: 0 | F35: 0 | G35: 0 | H35: 0 | I35: 0 | J35: 0 | K35: 0 | L35: 0 | P35: =SUM(D35:O35) -> 0 | Q35: - | S35: =IF(Q35<70,C35*2.936/100,0) -> 0
A36: 31 | B36: Sukawening | C36: 0 | D36: 0 | E36: 0 | F36: 0 | G36: 0 | H36: 0 | I36: 0 | J36: 0 | K36: 0 | L36: 0 | P36: =SUM(D36:O36) -> 0 | Q36: - | S36: =IF(Q36<70,C36*2.936/100,0) -> 0
A37: 32 | B37: Karang Tengah | C37: 0 | D37: 0 | E37: 0 | F37: 0 | G37: 0 | H37: 0 | I37: 0 | J37: 0 | K37: 0 | L37: 0 | P37: =SUM(D37:O37) -> 0 | Q37: - | S37: =IF(Q37<70,C37*2.936/100,0) -> 0
... A46: 41 | B46: Limbangan | C46: 0 | D46: 0 | E46: 0 | F46: 0 | G46: 0 | H46: 0 | I46: 0 | J46: 0 | K46: 0 | L46: 0 | P46: =SUM(D46:O46) -> 0 | Q46: - | S46: =IF(Q46<70,C46*2.936/100,0) -> 0
A47: 42 | B47: Selaawi | C47: 26 | D47: 0 | E47: 0 | F47: 0 | G47: 0 | H47: 0 | I47: 0 | J47: 0 | K47: 0 | L47: 0 | P47: =SUM(D47:O47) -> 0 | Q47: =P47/C47 -> 0 | S47: =IF(Q47<70,C47*2.936/100,0) -> 0.76336
A48: JUMLAH | C48: =SUM(C6:C47) -> 3274 | D48: =SUM(D6:D47) -> 205.55937 | E48: =SUM(E6:E47) -> 466.11183 | F48: =SUM(F6:F47) -> 419.7945 | G48: =SUM(G6:G47) -> 419.7945 | H48: =SUM(H6:H47) -> 391.8082 | I48: =SUM(I6:I47) -> 251.8767 | J48: =SUM(J6:J47) -> 195.9041 | ... P48: =SUM(P6:P47) -> 2602.7259 | Q48: =P48/C48 -> 0.7949682 | S48: =SUM(S6:S47) -> 96.12464
B51: =D48/C51*100 -> 7.345 | C51: 2798.63 | D51: =B51 -> 7.345 | E51: =24-D51 -> 16.655 | F51: 15 | G51: 15 | H51: 14 | I51: 9 | J51: 7 | K51: 6 | L51: 3 | M51: 3 | N51: 2 | O51: 2
...

Sheet KOPI
A1: LAPORAN PRODUKSI KOPI 2025
A2: DINAS PERTANIAN KABUPATEN GARUT
A4: NO | B4: KECAMATAN | C4: Target Produksi Kopi Tahun 2025 | D4: HASIL PRODUKSI | P4: TOTAL | Q4: REALISASI
D5: JANUARI | E5: FEBRUARI | F5: MARET | G5: APRIL | H5: MEI | I5: JUNI | J5: JULI | K5: AGUSTUS | L5: SEPTEMBER | M5: OKTOBER | N5: NOVEMBER | O5: DESEMBER
A6: 1 | B6: Cisewu | C6: 124 | D6: 0 | E6: =SUM(D54:E54) -> 5.163 | F6: 8.605 | G6: 17.21 | H6: 25.815 | I6: 43.025 | J6: 36.141 | K6: 13.768 | L6: 12.047 | P6: =SUM(D6:O6) -> 161.774 | Q6: =P6/C6 -> 1.304629
A7: 2 | B7: Caringin | C7: 238 | D7: 0 | E7: =SUM(D55:E55) -> 6.252 | F7: 10.42 | G7: 20.84 | H7: 31.26 | I7: 52.1 | J7: 43.764 | K7: 16.672 | L7: 14.588 | P7: =SUM(D7:O7) -> 195.896 | Q7: =P7/C7 -> 0.82309244
A8: 3 | B8: Talegong | C8: 121 | D8: 0 | E8: =SUM(D56:E56) -> 5.301 | F8: 8.835 | G8: 17.67 | H8: 26.505 | I8: 44.175 | J8: 37.107 | K8: 14.136 | L8: 12.369 | P8: =SUM(D8:O8) -> 166.098 | Q8: =P8/C8 -> 1.3727107
A9: 4 | B9: Bungbulang | C9: 31 | D9: 0 | E9: =SUM(D57:E57) -> 1.2108 | F9: 2.018 | G9: 4.036 | H9: 6.054 | I9: 10.09 | J9: 8.4756 | K9: 3.2288 | L9: 2.8252 | P9: =SUM(D9:O9) -> 37.9384 | Q9: =P9/C9 -> 1.2238194
A10: 5 | B10: Mekar Mukti | C10: 61 | D10: 0 | E10: =SUM(D58:E58) -> 1.5231 | F10: 2.5385 | G10: 5.077 | H10: 7.6155 | I10: 12.6925 | J10: 10.6617 | K10: 4.0616 | L10: 3.5539 | P10: =SUM(D10:O10) -> 47.7238 | Q10: =P10/C10 -> 0.78235738
A11: 6 | B11: Pakenjeng | C11: 328 | D11: 0 | E11: =SUM(D59:E59) -> 12.741 | F11: 21.235 | G11: 42.47 | H11: 63.705 | I11: 106.175 | J11: 89.187 | K11: 33.976 | L11: 29.729 | P11: =SUM(D11:O11) -> 399.218 | Q11: =P11/C11 -> 1.217128
A12: 7 | B12: Pamulihan | C12: 229 | D12: 0 | E12: =SUM(D60:E60) -> 13.323 | F12: 22.205 | G12: 44.41 | H12: 66.615 | I12: 111.025 | J12: 93.261 | K12: 35.528 | L12: 31.087 | P12: =SUM(D12:O12) -> 417.454 | Q12: =P12/C12 -> 1.8229432
A13: 8 | B13: Cikelet | C13: 25 | D13: 0 | E13: =SUM(D61:E61) -> 0.93 | F13: 1.55 | G13: 3.1 | H13: 4.65 | I13: 7.75 | J13: 6.51 | K13: 2.48 | L13: 2.17 | P13: =SUM(D13:O13) -> 29.14 | Q13: =P13/C13 -> 1.1656
A14: 9 | B14: Pameungpeuk | C14: 0 | D14: 0 | E14: =SUM(D62:E62) -> 0 | F14: 0 | G14: 0 | H14: 0 | I14: 0 | J14: 0 | K14: 0 | L14: 0 | P14: =SUM(D14:O14) -> 0 | Q14: -
A15: 10 | B15: Cibalong | C15: 8 | D15: 0 | E15: =SUM(D63:E63) -> 0.2577 | F15: 0.4295 | G15: 0.859 | H15: 1.2885 | I15: 2.1475 | J15: 1.8039 | K15: 0.6872 | L15: 0.6013 | P15: =SUM(D15:O15) -> 8.0746 | Q15: =P15/C15 -> 1.009325
A16: 11 | B16: Cisompet | C16: 109 | D16: 0 | E16: =SUM(D64:E64) -> 3.96 | F16: 6.6 | G16: 13.2 | H16: 19.8 | I16: 33 | J16: 27.72 | K16: 10.56 | L16: 9.24 | P16: =SUM(D16:O16) -> 124.08 | Q16: =P16/C16 -> 1.1383486
A17: 12 | B17: Singajaya | C17: 12 | D17: 0 | E17: =SUM(D65:E65) -> 0.288 | F17: 0.48 | G17: 0.96 | H17: 1.44 | I17: 2.4 | J17: 2.016 | K17: 0.768 | L17: 0.672 | P17: =SUM(D17:O17) -> 9.024 | Q17: =P17/C17 -> 0.752
A18: 13 | B18: Cihurip | C18: 25 | D18: 0 | E18: =SUM(D66:E66) -> 0.831 | F18: 1.385 | G18: 2.77 | H18: 4.155 | I18: 6.925 | J18: 5.817 | K18: 2.216 | L18: 1.939 | P18: =SUM(D18:O18) -> 26.038 | Q18: =P18/C18 -> 1.04152
A19: 14 | B19: Peundeuy | C19: 9 | D19: 0 | E19: =SUM(D67:E67) -> 0.6753 | F19: 1.1255 | G19: 2.251 | H19: 3.3765 | I19: 5.6275 | J19: 4.7271 | K19: 1.8008 | L19: 1.5757 | P19: =SUM(D19:O19) -> 21.1594 | Q19: =P19/C19 -> 2.3510444
A20: 15 | B20: Cikajang | C20: 500 | D20: 0 | E20: =SUM(D68:E68) -> 15.759 | F20: 26.265 | G20: 52.53 | H20: 78.795 | I20: 131.325 | J20: 110.313 | K20: 42.024 | L20: 36.771 | P20: =SUM(D20:O20) -> 493.782 | Q20: =P20/C20 -> 0.987564
A21: 16 | B21: Banjarwangi | C21: 22 | D21: 0 | E21: =SUM(D69:E69) -> 0.897 | F21: 1.495 | G21: 2.99 | H21: 4.485 | I21: 7.475 | J21: 6.279 | K21: 2.392 | L21: 2.093 | P21: =SUM(D21:O21) -> 28.106 | Q21: =P21/C21 -> 1.2775455
A22: 17 | B22: Cilawu | C22: 41 | D22: 0 | E22: =SUM(D70:E70) -> 1.9104 | F22: 3.184 | G22: 6.368 | H22: 9.552 | I22: 15.92 | J22: 13.3728 | K22: 5.0944 | L22: 4.4576 | P22: =SUM(D22:O22) -> 59.8592 | Q22: =P22/C22 -> 1.4599805
A23: 18 | B23: Bayongbong | C23: 13 | D23: 0 | E23: =SUM(D71:E71) -> 0.4167 | F23: 0.6945 | G23: 1.389 | H23: 2.0835 | I23: 3.4725 | J23: 2.9169 | K23: 1.1112 | L23: 0.9723 | P23: =SUM(D23:O23) -> 13.0566 | Q23: =P23/C23 -> 1.0043538
A24: 19 | B24: Cigedug | C24: 87 | D24: 0 | E24: =SUM(D72:E72) -> 3.2961 | F24: 5.4935 | G24: 10.987 | H24: 16.4805 | I24: 27.4675 | J24: 23.0727 | K24: 8.7896 | L24: 7.6909 | P24: =SUM(D24:O24) -> 103.2778 | Q24: =P24/C24 -> 1.1871011
A25: 20 | B25: Cisurupan | C25: 229 | D25: 0 | E25: =SUM(D73:E73) -> 8.85 | F25: 14.75 | G25: 29.5 | H25: 44.25 | I25: 73.75 | J25: 61.95 | K25: 23.6 | L25: 20.65 | P25: =SUM(D25:O25) -> 277.3 | Q25: =P25/C25 -> 1.210917
A26: 21 | B26: Sukaresmi | C26: 52 | D26: 0 | E26: =SUM(D74:E74) -> 1.75977 | F26: 2.93295 | G26: 5.8659 | H26: 8.79885 | I26: 14.66475 | J26: 12.31839 | K26: 4.69272 | L26: 4.10613 | P26: =SUM(D26:O26) -> 55.13946 | Q26: =P26/C26 -> 1.0603742
... A29: 24 | B29: Tarogong Kaler | C29: 110 | D29: 0 | E29: =SUM(D77:E77) -> 1.059 | F29: 1.765 | G29: 3.53 | H29: 5.295 | I29: 8.825 | J29: 7.413 | K29: 2.824 | L29: 2.471 | P29: =SUM(D29:O29) -> 33.182 | Q29: =P29/C29 -> 0.30165455
A30: 25 | B30: Tarogong Kidul | C30: 0 | D30: 0 | E30: =SUM(D78:E78) -> 0 | F30: 0 | G30: 0 | H30: 0 | I30: 0 | J30: 0 | K30: 0 | L30: 0 | P30: =SUM(D30:O30) -> 0 | Q30: -
A31: 26 | B31: Garut Kota | C31: 47 | D31: 0 | E31: =SUM(D79:E79) -> 0.339 | F31: 0.565 | G31: 1.13 | H31: 1.695 | I31: 2.825 | J31: 2.373 | K31: 0.904 | L31: 0.791 | P31: =SUM(D31:O31) -> 10.622 | Q31: =P31/C31 -> 0.226
A32: 27 | B32: Karangpawitan | C32: 33 | D32: 0 | E32: =SUM(D80:E80) -> 0.954 | F32: 1.59 | G32: 3.18 | H32: 4.77 | I32: 7.95 | J32: 6.678 | K32: 2.544 | L32: 2.226 | P32: =SUM(D32:O32) -> 29.892 | Q32: =P32/C32 -> 0.90581818
A33: 28 | B33: Wanaraja | C33: 11 | D33: 0 | E33: =SUM(D81:E81) -> 0.744 | F33: 1.24 | G33: 2.48 | H33: 3.72 | I33: 6.2 | J33: 5.208 | K33: 1.984 | L33: 1.736 | P33: =SUM(D33:O33) -> 23.312 | Q33: =P33/C33 -> 2.1192727
A34: 29 | B34: Pangatikan | C34: 35 | D34: 0 | E34: =SUM(D82:E82) -> 2.001 | F34: 3.335 | G34: 6.67 | H34: 10.005 | I34: 16.675 | J34: 14.007 | K34: 5.336 | L34: 4.669 | P34: =SUM(D34:O34) -> 62.698 | Q34: =P34/C34 -> 1.7913714
A35: 30 | B35: Sucinaraja | C35: 7 | D35: 0 | E35: =SUM(D83:E83) -> 0.84 | F35: 1.4 | G35: 2.8 | H35: 4.2 | I35: 7 | J35: 5.88 | K35: 2.24 | L35: 1.96 | P35: =SUM(D35:O35) -> 26.32 | Q35: =P35/C35 -> 3.76
A36: 31 | B36: Sukawening | C36: 22 | D36: 0 | E36: =SUM(D84:E84) -> 1.359 | F36: 2.265 | G36: 4.53 | H36: 6.795 | I36: 11.325 | J36: 9.513 | K36: 3.624 | L36: 3.171 | P36: =SUM(D36:O36) -> 42.582 | Q36: =P36/C36 -> 1.9355455
A37: 32 | B37: Karang Tengah | C37: 25 | D37: 0 | E37: =SUM(D85:E85) -> 1.65 | F37: 2.75 | G37: 5.5 | H37: 8.25 | I37: 13.75 | J37: 11.55 | K37: 4.4 | L37: 3.85 | P37: =SUM(D37:O37) -> 51.7 | Q37: =P37/C37 -> 2.068
A38: 33 | B38: Banyuresmi | C38: 1 | D38: 0 | E38: =SUM(D86:E86) -> 0.0312 | F38: 0.052 | G38: 0.104 | H38: 0.156 | I38: 0.26 | J38: 0.2184 | K38: 0.0832 | L38: 0.0728 | P38: =SUM(D38:O38) -> 0.9776 | Q38: =P38/C38 -> 0.9776
A39: 34 | B39: Leles | C39: 3 | D39: 0 | E39: =SUM(D87:E87) -> 0.3714 | F39: 0.619 | G39: 1.238 | H39: 1.857 | I39: 3.095 | J39: 2.5998 | K39: 0.9904 | L39: 0.8666 | P39: =SUM(D39:O39) -> 11.6372 | Q39: =P39/C39 -> 3.8790667
A40: 35 | B40: Leuwigoong | C40: 0 | D40: 0 | E40: =SUM(D88:E88) -> 0 | F40: 0 | G40: 0 | H40: 0 | I40: 0 | J40: 0 | K40: 0 | L40: 0 | P40: =SUM(D40:O40) -> 0 | Q40: -
A41: 36 | B41: Kadungora | C41: 19 | D41: 0 | E41: =SUM(D89:E89) -> 1.86 | F41: 3.1 | G41: 6.2 | H41: 9.3 | I41: 15.5 | J41: 13.02 | K41: 4.96 | L41: 4.34 | P41: =SUM(D41:O41) -> 58.28 | Q41: =P41/C41 -> 3.0673684
A42: 37 | B42: Cibiuk | C42: 1 | D42: 0 | E42: =SUM(D90:E90) -> 0.0225 | F42: 0.0375 | G42: 0.075 | H42: 0.1125 | I42: 0.1875 | J42: 0.1575 | K42: 0.06 | L42: 0.0525 | P42: =SUM(D42:O42) -> 0.705 | Q42: =P42/C42 -> 0.705
A43: 38 | B43: Cibatu | C43: 17 | D43: 0 | E43: =SUM(D91:E91) -> 0.546 | F43: 0.91 | G43: 1.82 | H43: 2.73 | I43: 4.55 | J43: 3.822 | K43: 1.456 | L43: 1.274 | P43: =SUM(D43:O43) -> 17.108 | Q43: =P43/C43 -> 1.0063529
...

Sheet Rekap
A1: KOMODITI | B1: TARGET PRODUKSI 2025 | C1: REALISASI 2025 | D1: PERSENTASE | E1: TARGET PRODUKSI DESEMBER 2025 | F1: REALISASI PRODUKSI DESEMBER 2025 | G1: PERSENTASE
A2: Padi | B2: =PADI!V9 -> 0 | C2: =PADI!W9 -> 0 | D2: =PADI!X9 -> 0 | E2: =PADI!Y9 -> 0 | F2: =PADI!Z9 -> 0 | G2: =PADI!AA9 -> 0 | H2: Meningkatkan Produksi Padi | I2: ="Laporan Produksi "&A2 -> Laporan Produksi Padi | J2: https://drive.google.com/file/d/16qvqq4kC0CM7KxhEaWpVRedHKCpf1RmG/view?usp=drive_link | K2: Jumlah Produksi Padi tahun 2025 sebanyak 707237 ton telah tercapai sampai dengan Desember 2025 sebanyak 701430 Ton atau 0,991789173926138 Telah disajikan dukungan Bidang-Bidang terhadap pencapaian target produksi pada 10 (sepuluh) komoditas utama Dinas Pertanian dengan menyajikan upaya-upaya yang telah dilakukan disertai dengan dokumentasi berupa foto. Pencapaian target 2025 "DIATAS EKSPEKTASI";
A3: Jagung | B3: =JAGUNG!V9 -> 0 | C3: =JAGUNG!W9 -> 0 | D3: =JAGUNG!X9 -> 0 | E3: =JAGUNG!Y9 -> 0 | F3: =JAGUNG!Z9 -> 0 | G3: =JAGUNG!AA9 -> 0 | H3: Meningkatkan Produksi Jagung | I3: ="Laporan Produksi "&A3 -> Laporan Produksi Jagung | J3: https://drive.google.com/file/d/1WMjXaoT1vTwQPciwQSfbH5gf1eUFnA9E/view?usp=drive_link | K3: Jumlah Produksi Padi tahun 2025 sebanyak 521662 ton telah tercapai sampai dengan Desember 2025 sebanyak 437500 Ton atau 0,83866564940517 Telah disajikan dukungan Bidang-Bidang terhadap pencapaian target produksi pada 10 (sepuluh) komoditas utama Dinas Pertanian dengan menyajikan upaya-upaya yang telah dilakukan disertai dengan dokumentasi berupa foto. Pencapaian target 2025 "DIATAS EKSPEKTASI";
A4: Cabe | B4: =CABAI!V9 -> 0 | C4: =CABAI!W9 -> 0 | D4: =CABAI!X9 -> 0 | E4: =CABAI!Y9 -> 0 | F4: =CABAI!Z9 -> 0 | G4: =CABAI!AA9 -> 0 | H4: Meningkatkan Produksi Cabai | I4: ="Laporan Produksi "&A4 -> Laporan Produksi Cabe | J4: https://drive.google.com/file/d/1oJoEMB1KamipM6kS4X1vlRkpq4qQfebA/view?usp=drive_link | K4: Jumlah Produksi Padi tahun 2025 sebanyak 158958 ton telah tercapai sampai dengan Desember 2025 sebanyak 160286 Ton atau 1,00835440808264 Telah disajikan dukungan Bidang-Bidang terhadap pencapaian target produksi pada 10 (sepuluh) komoditas utama Dinas Pertanian dengan menyajikan upaya-upaya yang telah dilakukan disertai dengan dokumentasi berupa foto. Pencapaian target 2025 "DIATAS EKSPEKTASI";
A5: Bawang Merah | B5: ='BAWANG MERAH'!V9 -> 0 | C5: ='BAWANG MERAH'!W9 -> 0 | D5: ='BAWANG MERAH'!X9 -> 0 | E5: ='BAWANG MERAH'!Y9 -> 0 | F5: ='BAWANG MERAH'!Z9 -> 0 | G5: ='BAWANG MERAH'!AA9 -> 0 | H5: Meningkatkan Produksi Bawang Merah | I5: ="Laporan Produksi "&A5 -> Laporan Produksi Bawang Merah | J5: https://drive.google.com/file/d/1Rv9qVinDkkjchVfD_5N2_RcAui1tLmCH/view?usp=drive_link | K5: Jumlah Produksi Padi tahun 2025 sebanyak 30638 ton telah tercapai sampai dengan Desember 2025 sebanyak 36558 Ton atau 1,19322410078987 Telah disajikan dukungan Bidang-Bidang terhadap pencapaian target produksi pada 10 (sepuluh) komoditas utama Dinas Pertanian dengan menyajikan upaya-upaya yang telah dilakukan disertai dengan dokumentasi berupa foto. Pencapaian target 2025 "DIATAS EKSPEKTASI";
A6: Kentang | B6: =KENTANG!V9 -> 0 | C6: =KENTANG!W9 -> 0 | D6: =KENTANG!X9 -> 0 | E6: =KENTANG!Y9 -> 0 | F6: =KENTANG!Z9 -> 0 | G6: =KENTANG!AA9 -> 0 | H6: Meningkatkan Produksi Kentang | I6: ="Laporan Produksi "&A6 -> Laporan Produksi Kentang | J6: https://drive.google.com/file/d/1EDiuQbrjYtseQ624OwqK0VlesBsiwvra/view?usp=drive_link | K6: Jumlah Produksi Padi tahun 2025 sebanyak 190727 ton telah tercapai sampai dengan Desember 2025 sebanyak 157607,3 Ton atau 0,826350228336837 Telah disajikan dukungan Bidang-Bidang terhadap pencapaian target produksi pada 10 (sepuluh) komoditas utama Dinas Pertanian dengan menyajikan upaya-upaya yang telah dilakukan disertai dengan dokumentasi berupa foto. Pencapaian target 2025 "DIATAS EKSPEKTASI";
A7: Jahe | B7: =JAHE!V9 -> 0 | C7: =JAHE!W9 -> 0 | D7: =JAHE!X9 -> 0 | E7: =JAHE!Y9 -> 0 | F7: =JAHE!Z9 -> 0 | G7: =JAHE!AA9 -> 0 | H7: Meningkatkan Produksi Jahe | I7: ="Laporan Produksi "&A7 -> Laporan Produksi Jahe | J7: https://drive.google.com/file/d/1OAayQcEI8fgMpkEyc-cMhNmVFKsGVdYG/view?usp=drive_link | K7: Jumlah Produksi Padi tahun 2025 sebanyak 7410 ton telah tercapai sampai dengan Desember 2025 sebanyak 12037,09 Ton atau 1,62443859649123 Telah disajikan dukungan Bidang-Bidang terhadap pencapaian target produksi pada 10 (sepuluh) komoditas utama Dinas Pertanian dengan menyajikan upaya-upaya yang telah dilakukan disertai dengan dokumentasi berupa foto. Pencapaian target 2025 "DIATAS EKSPEKTASI";
A8: Jeruk | B8: =JERUK!V10 -> 0 | C8: =JERUK!W10 -> 0 | D8: =JERUK!X10 -> 0 | E8: =JERUK!Y10 -> 0 | F8: =JERUK!Z10 -> 0 | G8: =JERUK!AA10 -> 0 | H8: Meningkatkan Produksi Jeruk | I8: ="Laporan Produksi "&A8 -> Laporan Produksi Jeruk | J8: https://drive.google.com/file/d/1GIudTyy0Rt0MUCgP81bhbD8UX6NN6FHN/view?usp=drive_link | K8: Jumlah Produksi Padi tahun 2025 sebanyak 13742 ton telah tercapai sampai dengan Desember 2025 sebanyak 7699 Ton atau 0,560253238247708 Telah disajikan dukungan Bidang-Bidang terhadap pencapaian target produksi pada 10 (sepuluh) komoditas utama Dinas Pertanian dengan menyajikan upaya-upaya yang telah dilakukan disertai dengan dokumentasi berupa foto. Pencapaian target 2025 "DIATAS EKSPEKTASI";
A9: Kopi | B9: =KOPI!V9 -> 0 | C9: =KOPI!W9 -> 0 | D9: =KOPI!X9 -> 0 | E9: =KOPI!Y9 -> 0 | F9: =KOPI!Z9 -> 0 | G9: =KOPI!AA9 -> 0 | H9: Meningkatkan Produksi Kopi | I9: ="Laporan Produksi "&A9 -> Laporan Produksi Kopi | J9: https://drive.google.com/file/d/12V1vYzRvGPA3WiowUFbJrSP0sIAidnjh/view?usp=drive_link | K9: Jumlah Produksi Padi tahun 2025 sebanyak 2866 ton telah tercapai sampai dengan Desember 2025 sebanyak 3466,12346 Ton atau 1,2093940893231 Telah disajikan dukungan Bidang-Bidang terhadap pencapaian target produksi pada 10 (sepuluh) komoditas utama Dinas Pertanian dengan menyajikan upaya-upaya yang telah dilakukan disertai dengan dokumentasi berupa foto. Pencapaian target 2025 "DIATAS EKSPEKTASI";
A10: Teh | B10: =TEH!V9 -> 0 | C10: =TEH!W9 -> 0 | D10: =TEH!X9 -> 0 | E10: =TEH!Y9 -> 0 | F10: =TEH!Z9 -> 0 | G10: =TEH!AA9 -> 0 | H10: Meningkatkan Produksi Teh | I10: ="Laporan Produksi "&A10 -> Laporan Produksi Teh | J10: https://drive.google.com/file/d/1EQ8krRNB4C09H5dHRCVMfhsi2oKhl_co/view?usp=drive_link | K10: Jumlah Produksi Padi tahun 2025 sebanyak 3274 ton telah tercapai sampai dengan Desember 2025 sebanyak 2602,7259 Ton atau 0,794968204031765 Telah disajikan dukungan Bidang-Bidang terhadap pencapaian target produksi pada 10 (sepuluh) komoditas utama Dinas Pertanian dengan menyajikan upaya-upaya yang telah dilakukan disertai dengan dokumentasi berupa foto. Pencapaian target 2025 "DIATAS EKSPEKTASI";
A11: Tembakau | B11: =#REF! -> #REF! | C11: =#REF! -> #REF! | D11: =#REF! -> #REF! | E11: =#REF! -> #REF! | F11: =#REF! -> #REF! | G11: =#REF! -> #REF! | H11: Meningkatkan Produksi Tembakau | I11: ="Laporan Produksi "&A11 -> Laporan Produksi Tembakau | J11: https://drive.google.com/file/d/1Kr4Hts8G2bWEjBpX2duGEFyf_tfMXDyg/view?usp=drive_link | K11: Jumlah Produksi Padi tahun 2025 sebanyak 3180 ton telah tercapai sampai dengan Desember 2025 sebanyak 3272,5479128 Ton atau 1,0291031172327 Telah disajikan dukungan Bidang-Bidang terhadap pencapaian target produksi pada 10 (sepuluh) komoditas utama Dinas Pertanian dengan menyajikan upaya-upaya yang telah dilakukan disertai dengan dokumentasi berupa foto. Pencapaian target 2025 "DIATAS EKSPEKTASI";
